Workbook

Sheet Resumen carta
A1: Resumen de carta · La Tasca del Puerto · Guía de Isora, Tenerife
A2: Zona fiscal: Canarias (IGIC 7%) · Food cost objetivo: 30%
A4: Código | B4: Plato | C4: Categoría | D4: Raciones | E4: Coste/ración (€) | F4: PVP (€) | G4: Food cost (%) | H4: Margen bruto (€) | I4: Margen (%) | J4: PVP recomendado (€) | K4: Diagnóstico
A5: PL-001 | B5: Papas arrugadas con mojo rojo | C5: Entrante | D5: ='Papas arrugadas con mojo rojo'!B19 -> 1 | E5: ='Papas arrugadas con mojo rojo'!B20 -> 0.8631685 | F5: ='Papas arrugadas con mojo rojo'!B22 -> 4.5 | G5: ='Papas arrugadas con mojo rojo'!B25 -> 20.524229 | H5: ='Papas arrugadas con mojo rojo'!B26 -> 3.342439 | I5: ='Papas arrugadas con mojo rojo'!B27 -> 79.475771 | J5: ='Papas arrugadas con mojo rojo'!B29 -> 3.1 | K5: ='Papas arrugadas con mojo rojo'!B30 -> Rentable
A6: PL-002 | B6: Ropa vieja canaria | C6: Principal | D6: ='Ropa vieja canaria'!B20 -> 1 | E6: ='Ropa vieja canaria'!B21 -> 3.3041514 | F6: ='Ropa vieja canaria'!B23 -> 9.5 | G6: ='Ropa vieja canaria'!B26 -> 37.215179 | H6: ='Ropa vieja canaria'!B27 -> 5.5743533 | I6: ='Ropa vieja canaria'!B28 -> 62.784821 | J6: ='Ropa vieja canaria'!B30 -> 11.8 | K6: ='Ropa vieja canaria'!B31 -> No rentable
A7: PL-003 | B7: Vieja a la espalda con mojo verde | C7: Principal | D7: ='Vieja a la espalda con mojo ver'!B18 -> 1 | E7: ='Vieja a la espalda con mojo ver'!B19 -> 6.7177446 | F7: ='Vieja a la espalda con mojo ver'!B21 -> 14 | G7: ='Vieja a la espalda con mojo ver'!B24 -> 51.342762 | H7: ='Vieja a la espalda con mojo ver'!B25 -> 6.3663676 | I7: ='Vieja a la espalda con mojo ver'!B26 -> 48.657238 | J7: ='Vieja a la espalda con mojo ver'!B28 -> 24 | K7: ='Vieja a la espalda con mojo ver'!B29 -> No rentable
A8: PL-004 | B8: Queso asado con miel de palma | C8: Entrante | D8: ='Queso asado con miel de palma'!B15 -> 1 | E8: ='Queso asado con miel de palma'!B16 -> 1.9769907 | F8: ='Queso asado con miel de palma'!B18 -> 7 | G8: ='Queso asado con miel de palma'!B21 -> 30.219716 | H8: ='Queso asado con miel de palma'!B22 -> 4.5650653 | I8: ='Queso asado con miel de palma'!B23 -> 69.780284 | J8: ='Queso asado con miel de palma'!B25 -> 7.1 | K8: ='Queso asado con miel de palma'!B26 -> Revisar
A9: PL-005 | B9: Plátano frito con gofio y miel | C9: Postre | D9: ='Plátano frito con gofio y miel'!B15 -> 1 | E9: ='Plátano frito con gofio y miel'!B16 -> 0.89900571 | F9: ='Plátano frito con gofio y miel'!B18 -> 5.5 | G9: ='Plátano frito con gofio y miel'!B21 -> 17.489748 | H9: ='Plátano frito con gofio y miel'!B22 -> 4.2411812 | I9: ='Plátano frito con gofio y miel'!B23 -> 82.510252 | J9: ='Plátano frito con gofio y miel'!B25 -> 3.25 | K9: ='Plátano frito con gofio y miel'!B26 -> Rentable
A11: Food cost medio carta | G11: =AVERAGE(G5:G9) -> 31.358327
A12: Platos a revisar / no rentables | G12: =COUNTIF(K5:K9,"Revisar")+COUNTIF(K5:K9,"No rentable") -> 3

Sheet Papas arrugadas con mojo rojo
A1: Escandallo · Papas arrugadas con mojo rojo
A2: Código: PL-001 · Categoría: Entrante · Zona: Canarias (IGIC)
A4: Ingrediente | B4: Cantidad | C4: Unidad | D4: Precio compra (€/kg-l) | E4: Merma % | F4: Coste útil (€/kg-l) | G4: Coste línea (€)
A5: Papa negra canaria | B5: 250 | C5: kg (g/ml) | D5: 1.85 | E5: 8 | F5: =D5/(1-E5/100) -> 2.0108696 | G5: =(B5/1000)*F5 -> 0.50271739
A6: Pimiento rojo | B6: 30 | C6: kg (g/ml) | D6: 3.05 | E6: 15 | F6: =D6/(1-E6/100) -> 3.5882353 | G6: =(B6/1000)*F6 -> 0.10764706
A7: Aceite de oliva | B7: 15 | C7: l (g/ml) | D7: 6.5 | E7: 0 | F7: =D7/(1-E7/100) -> 6.5 | G7: =(B7/1000)*F7 -> 0.0975
A8: Ajo | B8: 6 | C8: kg (g/ml) | D8: 8 | E8: 12 | F8: =D8/(1-E8/100) -> 9.0909091 | G8: =(B8/1000)*F8 -> 0.054545455
A9: Comino molido | B9: 1 | C9: kg (g/ml) | D9: 14 | E9: 0 | F9: =D9/(1-E9/100) -> 14 | G9: =(B9/1000)*F9 -> 0.014
A10: Sal gruesa | B10: 8 | C10: kg (g/ml) | D10: 0.8 | E10: 0 | F10: =D10/(1-E10/100) -> 0.8 | G10: =(B10/1000)*F10 -> 0.0064
A11: Vinagre de vino | B11: 5 | C11: l (g/ml) | D11: 1.5 | E11: 0 | F11: =D11/(1-E11/100) -> 1.5 | G11: =(B11/1000)*F11 -> 0.0075
A12: Pimentón | B12: 2 | C12: kg (g/ml) | D12: 12 | E12: 0 | F12: =D12/(1-E12/100) -> 12 | G12: =(B12/1000)*F12 -> 0.024
A14: Coste ingredientes (€) | B14: =SUM(G5:G12) -> 0.8143099
A15: Condimentos y varios (%) | B15: 6
A16: Extras (€) | B16: =B14*B15/100 -> 0.048858594
A17: Packaging (€) | B17: 0
A18: Coste directo (€) | B18: =B14+B16+B17 -> 0.8631685
A19: Raciones | B19: 1
A20: Coste por ración (€) | B20: =B18/B19 -> 0.8631685
A22: PVP carta (€, con IGIC) | B22: 4.5
A23: IGIC / IVA (%) | B23: 7
A24: PVP sin impuesto (€) | B24: =B22/(1+B23/100) -> 4.2056075
A25: Food cost (%) | B25: =B20/B24*100 -> 20.524229
A26: Margen bruto (€) | B26: =B24-B20 -> 3.342439
A27: Margen (%) | B27: =B26/B24*100 -> 79.475771
A28: Food cost objetivo (%) | B28: 30
A29: PVP recomendado (€, con IGIC) | B29: =CEILING((B20/(B28/100))*(1+B23/100),0.05) -> 3.1
A30: Diagnóstico | B30: =IF(B25>B28+5,"No rentable",IF(B25>B28,"Revisar","Rentable")) -> Rentable
A32: Alérgenos (14 UE)
A33: Alérgeno | B33: Estado
A34: Cereales con gluten | B34: No contiene
A35: Crustáceos | B35: No contiene
A36: Huevos | B36: No contiene
A37: Pescado | B37: No contiene
A38: Cacahuetes | B38: No contiene
A39: Soja | B39: No contiene
A40: Leche y lactosa | B40: No contiene
A41: Frutos de cáscara | B41: No contiene
A42: Apio | B42: No contiene
A43: Mostaza | B43: No contiene
A44: Sésamo | B44: No contiene
...

Sheet Ropa vieja canaria
A1: Escandallo · Ropa vieja canaria
A2: Código: PL-002 · Categoría: Principal · Zona: Canarias (IGIC)
A4: Ingrediente | B4: Cantidad | C4: Unidad | D4: Precio compra (€/kg-l) | E4: Merma % | F4: Coste útil (€/kg-l) | G4: Coste línea (€)
A5: Falda de ternera | B5: 160 | C5: kg (g/ml) | D5: 9.8 | E5: 20 | F5: =D5/(1-E5/100) -> 12.25 | G5: =(B5/1000)*F5 -> 1.96
A6: Garbanzo cocido | B6: 120 | C6: kg (g/ml) | D6: 2.2 | E6: 0 | F6: =D6/(1-E6/100) -> 2.2 | G6: =(B6/1000)*F6 -> 0.264
A7: Papa negra canaria | B7: 120 | C7: kg (g/ml) | D7: 1.85 | E7: 8 | F7: =D7/(1-E7/100) -> 2.0108696 | G7: =(B7/1000)*F7 -> 0.24130435
A8: Cebolla | B8: 50 | C8: kg (g/ml) | D8: 1.1 | E8: 10 | F8: =D8/(1-E8/100) -> 1.2222222 | G8: =(B8/1000)*F8 -> 0.061111111
A9: Pimiento rojo | B9: 40 | C9: kg (g/ml) | D9: 3.05 | E9: 15 | F9: =D9/(1-E9/100) -> 3.5882353 | G9: =(B9/1000)*F9 -> 0.14352941
A10: Tomate | B10: 60 | C10: kg (g/ml) | D10: 1.95 | E10: 10 | F10: =D10/(1-E10/100) -> 2.1666667 | G10: =(B10/1000)*F10 -> 0.13
A11: Aceite de oliva | B11: 20 | C11: l (g/ml) | D11: 6.5 | E11: 0 | F11: =D11/(1-E11/100) -> 6.5 | G11: =(B11/1000)*F11 -> 0.13
A12: Ajo | B12: 5 | C12: kg (g/ml) | D12: 8 | E12: 12 | F12: =D12/(1-E12/100) -> 9.0909091 | G12: =(B12/1000)*F12 -> 0.045454545
A13: Vino blanco de cocina | B13: 30 | C13: l (g/ml) | D13: 2.8 | E13: 0 | F13: =D13/(1-E13/100) -> 2.8 | G13: =(B13/1000)*F13 -> 0.084
A15: Coste ingredientes (€) | B15: =SUM(G5:G13) -> 3.0593994
A16: Condimentos y varios (%) | B16: 8
A17: Extras (€) | B17: =B15*B16/100 -> 0.24475195
A18: Packaging (€) | B18: 0
A19: Coste directo (€) | B19: =B15+B17+B18 -> 3.3041514
A20: Raciones | B20: 1
A21: Coste por ración (€) | B21: =B19/B20 -> 3.3041514
A23: PVP carta (€, con IGIC) | B23: 9.5
A24: IGIC / IVA (%) | B24: 7
A25: PVP sin impuesto (€) | B25: =B23/(1+B24/100) -> 8.8785047
A26: Food cost (%) | B26: =B21/B25*100 -> 37.215179
A27: Margen bruto (€) | B27: =B25-B21 -> 5.5743533
A28: Margen (%) | B28: =B27/B25*100 -> 62.784821
A29: Food cost objetivo (%) | B29: 30
A30: PVP recomendado (€, con IGIC) | B30: =CEILING((B21/(B29/100))*(1+B24/100),0.05) -> 11.8
A31: Diagnóstico | B31: =IF(B26>B29+5,"No rentable",IF(B26>B29,"Revisar","Rentable")) -> No rentable
A33: Alérgenos (14 UE)
A34: Alérgeno | B34: Estado
A35: Cereales con gluten | B35: No contiene
A36: Crustáceos | B36: No contiene
A37: Huevos | B37: No contiene
A38: Pescado | B38: No contiene
A39: Cacahuetes | B39: No contiene
A40: Soja | B40: No contiene
A41: Leche y lactosa | B41: No contiene
A42: Frutos de cáscara | B42: No contiene
A43: Apio | B43: No contiene
A44: Mostaza | B44: No contiene
...

Sheet Vieja a la espalda con mojo ver
A1: Escandallo · Vieja a la espalda con mojo verde
A2: Código: PL-003 · Categoría: Principal · Zona: Canarias (IGIC)
A4: Ingrediente | B4: Cantidad | C4: Unidad | D4: Precio compra (€/kg-l) | E4: Merma % | F4: Coste útil (€/kg-l) | G4: Coste línea (€)
A5: Vieja (pescado local) | B5: 300 | C5: kg (g/ml) | D5: 12.5 | E5: 35 | F5: =D5/(1-E5/100) -> 19.230769 | G5: =(B5/1000)*F5 -> 5.7692308
A6: Papa negra canaria | B6: 150 | C6: kg (g/ml) | D6: 1.85 | E6: 8 | F6: =D6/(1-E6/100) -> 2.0108696 | G6: =(B6/1000)*F6 -> 0.30163043
A7: Pimiento verde | B7: 25 | C7: kg (g/ml) | D7: 2.4 | E7: 15 | F7: =D7/(1-E7/100) -> 2.8235294 | G7: =(B7/1000)*F7 -> 0.070588235
A8: Aceite de oliva | B8: 20 | C8: l (g/ml) | D8: 6.5 | E8: 0 | F8: =D8/(1-E8/100) -> 6.5 | G8: =(B8/1000)*F8 -> 0.13
A9: Ajo | B9: 6 | C9: kg (g/ml) | D9: 8 | E9: 12 | F9: =D9/(1-E9/100) -> 9.0909091 | G9: =(B9/1000)*F9 -> 0.054545455
A10: Sal gruesa | B10: 5 | C10: kg (g/ml) | D10: 0.8 | E10: 0 | F10: =D10/(1-E10/100) -> 0.8 | G10: =(B10/1000)*F10 -> 0.004
A11: Vinagre de vino | B11: 5 | C11: l (g/ml) | D11: 1.5 | E11: 0 | F11: =D11/(1-E11/100) -> 1.5 | G11: =(B11/1000)*F11 -> 0.0075
A13: Coste ingredientes (€) | B13: =SUM(G5:G11) -> 6.3374949
A14: Condimentos y varios (%) | B14: 6
A15: Extras (€) | B15: =B13*B14/100 -> 0.38024969
A16: Packaging (€) | B16: 0
A17: Coste directo (€) | B17: =B13+B15+B16 -> 6.7177446
A18: Raciones | B18: 1
A19: Coste por ración (€) | B19: =B17/B18 -> 6.7177446
A21: PVP carta (€, con IGIC) | B21: 14
A22: IGIC / IVA (%) | B22: 7
A23: PVP sin impuesto (€) | B23: =B21/(1+B22/100) -> 13.084112
A24: Food cost (%) | B24: =B19/B23*100 -> 51.342762
A25: Margen bruto (€) | B25: =B23-B19 -> 6.3663676
A26: Margen (%) | B26: =B25/B23*100 -> 48.657238
A27: Food cost objetivo (%) | B27: 30
A28: PVP recomendado (€, con IGIC) | B28: =CEILING((B19/(B27/100))*(1+B22/100),0.05) -> 24
A29: Diagnóstico | B29: =IF(B24>B27+5,"No rentable",IF(B24>B27,"Revisar","Rentable")) -> No rentable
A31: Alérgenos (14 UE)
A32: Alérgeno | B32: Estado
A33: Cereales con gluten | B33: No contiene
A34: Crustáceos | B34: No contiene
A35: Huevos | B35: No contiene
A36: Pescado | B36: Contiene
A37: Cacahuetes | B37: No contiene
A38: Soja | B38: No contiene
A39: Leche y lactosa | B39: No contiene
A40: Frutos de cáscara | B40: No contiene
A41: Apio | B41: No contiene
A42: Mostaza | B42: No contiene
A43: Sésamo | B43: No contiene
... A46: Moluscos | B46: No contiene
...

Sheet Queso asado con miel de palma
A1: Escandallo · Queso asado con miel de palma
A2: Código: PL-004 · Categoría: Entrante · Zona: Canarias (IGIC)
A4: Ingrediente | B4: Cantidad | C4: Unidad | D4: Precio compra (€/kg-l) | E4: Merma % | F4: Coste útil (€/kg-l) | G4: Coste línea (€)
A5: Queso canario semicurado | B5: 140 | C5: kg (g/ml) | D5: 11 | E5: 5 | F5: =D5/(1-E5/100) -> 11.578947 | G5: =(B5/1000)*F5 -> 1.6210526
A6: Miel de palma | B6: 15 | C6: l (g/ml) | D6: 15 | E6: 0 | F6: =D6/(1-E6/100) -> 15 | G6: =(B6/1000)*F6 -> 0.225
A7: Gofio de millo | B7: 8 | C7: kg (g/ml) | D7: 2.8 | E7: 0 | F7: =D7/(1-E7/100) -> 2.8 | G7: =(B7/1000)*F7 -> 0.0224
A8: Aceite de oliva | B8: 5 | C8: l (g/ml) | D8: 6.5 | E8: 0 | F8: =D8/(1-E8/100) -> 6.5 | G8: =(B8/1000)*F8 -> 0.0325
A10: Coste ingredientes (€) | B10: =SUM(G5:G8) -> 1.9009526
A11: Condimentos y varios (%) | B11: 4
A12: Extras (€) | B12: =B10*B11/100 -> 0.076038105
A13: Packaging (€) | B13: 0
A14: Coste directo (€) | B14: =B10+B12+B13 -> 1.9769907
A15: Raciones | B15: 1
A16: Coste por ración (€) | B16: =B14/B15 -> 1.9769907
A18: PVP carta (€, con IGIC) | B18: 7
A19: IGIC / IVA (%) | B19: 7
A20: PVP sin impuesto (€) | B20: =B18/(1+B19/100) -> 6.5420561
A21: Food cost (%) | B21: =B16/B20*100 -> 30.219716
A22: Margen bruto (€) | B22: =B20-B16 -> 4.5650653
A23: Margen (%) | B23: =B22/B20*100 -> 69.780284
A24: Food cost objetivo (%) | B24: 30
A25: PVP recomendado (€, con IGIC) | B25: =CEILING((B16/(B24/100))*(1+B19/100),0.05) -> 7.1
A26: Diagnóstico | B26: =IF(B21>B24+5,"No rentable",IF(B21>B24,"Revisar","Rentable")) -> Revisar
A28: Alérgenos (14 UE)
A29: Alérgeno | B29: Estado
A30: Cereales con gluten | B30: Pendiente de validar
A31: Crustáceos | B31: No contiene
A32: Huevos | B32: No contiene
A33: Pescado | B33: No contiene
A34: Cacahuetes | B34: No contiene
A35: Soja | B35: No contiene
A36: Leche y lactosa | B36: Contiene
A37: Frutos de cáscara | B37: No contiene
A38: Apio | B38: No contiene
A39: Mostaza | B39: No contiene
A40: Sésamo | B40: No contiene
... A43: Moluscos | B43: No contiene
A45: Validar siempre con información real de proveedor y etiquetado de producto antes de publicar la carta.
A47: Ficha técnica
A48: Elaboración | B48: Marcar el queso a la plancha por ambas caras. Emplatar con miel de palma y espolvoreo de gofio tostado.
...

Sheet Plátano frito con gofio y miel
A1: Escandallo · Plátano frito con gofio y miel
A2: Código: PL-005 · Categoría: Postre · Zona: Canarias (IGIC)
A4: Ingrediente | B4: Cantidad | C4: Unidad | D4: Precio compra (€/kg-l) | E4: Merma % | F4: Coste útil (€/kg-l) | G4: Coste línea (€)
A5: Plátano de Canarias | B5: 180 | C5: kg (g/ml) | D5: 2.3 | E5: 30 | F5: =D5/(1-E5/100) -> 3.2857143 | G5: =(B5/1000)*F5 -> 0.59142857
A6: Miel de palma | B6: 12 | C6: l (g/ml) | D6: 15 | E6: 0 | F6: =D6/(1-E6/100) -> 15 | G6: =(B6/1000)*F6 -> 0.18
A7: Gofio de millo | B7: 10 | C7: kg (g/ml) | D7: 2.8 | E7: 0 | F7: =D7/(1-E7/100) -> 2.8 | G7: =(B7/1000)*F7 -> 0.028
A8: Aceite de oliva | B8: 10 | C8: l (g/ml) | D8: 6.5 | E8: 0 | F8: =D8/(1-E8/100) -> 6.5 | G8: =(B8/1000)*F8 -> 0.065
A10: Coste ingredientes (€) | B10: =SUM(G5:G8) -> 0.86442857
A11: Condimentos y varios (%) | B11: 4
A12: Extras (€) | B12: =B10*B11/100 -> 0.034577143
A13: Packaging (€) | B13: 0
A14: Coste directo (€) | B14: =B10+B12+B13 -> 0.89900571
A15: Raciones | B15: 1
A16: Coste por ración (€) | B16: =B14/B15 -> 0.89900571
A18: PVP carta (€, con IGIC) | B18: 5.5
A19: IGIC / IVA (%) | B19: 7
A20: PVP sin impuesto (€) | B20: =B18/(1+B19/100) -> 5.1401869
A21: Food cost (%) | B21: =B16/B20*100 -> 17.489748
A22: Margen bruto (€) | B22: =B20-B16 -> 4.2411812
A23: Margen (%) | B23: =B22/B20*100 -> 82.510252
A24: Food cost objetivo (%) | B24: 30
A25: PVP recomendado (€, con IGIC) | B25: =CEILING((B16/(B24/100))*(1+B19/100),0.05) -> 3.25
A26: Diagnóstico | B26: =IF(B21>B24+5,"No rentable",IF(B21>B24,"Revisar","Rentable")) -> Rentable
A28: Alérgenos (14 UE)
A29: Alérgeno | B29: Estado
A30: Cereales con gluten | B30: Pendiente de validar
A31: Crustáceos | B31: No contiene
A32: Huevos | B32: No contiene
A33: Pescado | B33: No contiene
A34: Cacahuetes | B34: No contiene
A35: Soja | B35: No contiene
A36: Leche y lactosa | B36: No contiene
A37: Frutos de cáscara | B37: No contiene
A38: Apio | B38: No contiene
A39: Mostaza | B39: No contiene
A40: Sésamo | B40: No contiene
... A43: Moluscos | B43: No contiene
A45: Validar siempre con información real de proveedor y etiquetado de producto antes de publicar la carta.
A47: Ficha técnica
A48: Elaboración | B48: Freír el plátano maduro en aceite a 170°C hasta dorar. Emplatar con gofio y miel de palma.
...
